2021-01-20 21:28:01,805 ERROR: Exception on /favicon.ico [GET] [in /home/jessah/blog/venv/lib/python3.8/site-packages/flask/app.py:1891]
Traceback (most recent call last):
  File "/home/jessah/blog/venv/lib/python3.8/site-packages/flask/app.py", line 1950, in full_dispatch_request
    rv = self.dispatch_request()
  File "/home/jessah/blog/venv/lib/python3.8/site-packages/flask/app.py", line 1926, in dispatch_request
    self.raise_routing_exception(req)
  File "/home/jessah/blog/venv/lib/python3.8/site-packages/flask/app.py", line 1908, in raise_routing_exception
    raise request.routing_exception
  File "/home/jessah/blog/venv/lib/python3.8/site-packages/flask/ctx.py", line 350, in match_request
    result = self.url_adapter.match(return_rule=True)
  File "/home/jessah/blog/venv/lib/python3.8/site-packages/werkzeug/routing.py", line 1945, in match
    raise NotFound()
werkzeug.exceptions.NotFound: 404 Not Found: The requested URL was not found on the server. If you entered the URL manually please check your spelling and try again.

During handling of the above exception, another exception occurred:

Traceback (most recent call last):
  File "/home/jessah/blog/venv/lib/python3.8/site-packages/flask/app.py", line 2447, in wsgi_app
    response = self.full_dispatch_request()
  File "/home/jessah/blog/venv/lib/python3.8/site-packages/flask/app.py", line 1952, in full_dispatch_request
    rv = self.handle_user_exception(e)
  File "/home/jessah/blog/venv/lib/python3.8/site-packages/flask/app.py", line 1816, in handle_user_exception
    return self.handle_http_exception(e)
  File "/home/jessah/blog/venv/lib/python3.8/site-packages/flask/app.py", line 1744, in handle_http_exception
    return handler(e)
  File "/home/jessah/blog/app/errors.py", line 6, in not_found_error
    return render_template('404.html'), 404
  File "/home/jessah/blog/venv/lib/python3.8/site-packages/flask/templating.py", line 138, in render_template
    ctx.app.jinja_env.get_or_select_template(template_name_or_list),
  File "/home/jessah/blog/venv/lib/python3.8/site-packages/jinja2/environment.py", line 930, in get_or_select_template
    return self.get_template(template_name_or_list, parent, globals)
  File "/home/jessah/blog/venv/lib/python3.8/site-packages/jinja2/environment.py", line 883, in get_template
    return self._load_template(name, self.make_globals(globals))
  File "/home/jessah/blog/venv/lib/python3.8/site-packages/jinja2/environment.py", line 857, in _load_template
    template = self.loader.load(self, name, globals)
  File "/home/jessah/blog/venv/lib/python3.8/site-packages/jinja2/loaders.py", line 127, in load
    code = environment.compile(source, name, filename)
  File "/home/jessah/blog/venv/lib/python3.8/site-packages/jinja2/environment.py", line 638, in compile
    self.handle_exception(source=source_hint)
  File "/home/jessah/blog/venv/lib/python3.8/site-packages/jinja2/environment.py", line 832, in handle_exception
    reraise(*rewrite_traceback_stack(source=source))
  File "/home/jessah/blog/venv/lib/python3.8/site-packages/jinja2/_compat.py", line 28, in reraise
    raise value.with_traceback(tb)
  File "/home/jessah/blog/app/templates/404.html", line 1, in template
    {% extend "base.html" %}
jinja2.exceptions.TemplateSyntaxError: Encountered unknown tag 'extend'.
2021-01-24 14:39:13,580 INFO: blog startup [in /home/jessah/blog/app/__init__.py:41]
2021-01-24 14:39:26,407 ERROR: Exception on /user/CJ [GET] [in /home/jessah/blog/venv/lib/python3.8/site-packages/flask/app.py:1891]
Traceback (most recent call last):
  File "/home/jessah/blog/venv/lib/python3.8/site-packages/flask/app.py", line 2447, in wsgi_app
    response = self.full_dispatch_request()
  File "/home/jessah/blog/venv/lib/python3.8/site-packages/flask/app.py", line 1952, in full_dispatch_request
    rv = self.handle_user_exception(e)
  File "/home/jessah/blog/venv/lib/python3.8/site-packages/flask/app.py", line 1821, in handle_user_exception
    reraise(exc_type, exc_value, tb)
  File "/home/jessah/blog/venv/lib/python3.8/site-packages/flask/_compat.py", line 39, in reraise
    raise value
  File "/home/jessah/blog/venv/lib/python3.8/site-packages/flask/app.py", line 1950, in full_dispatch_request
    rv = self.dispatch_request()
  File "/home/jessah/blog/venv/lib/python3.8/site-packages/flask/app.py", line 1936, in dispatch_request
    return self.view_functions[rule.endpoint](**req.view_args)
  File "/home/jessah/blog/venv/lib/python3.8/site-packages/flask_login/utils.py", line 272, in decorated_view
    return func(*args, **kwargs)
  File "/home/jessah/blog/app/routes.py", line 71, in user
    posts = user.posts.order_by(Post.timestamp,desc()).paginate(
NameError: name 'desc' is not defined
2021-01-24 14:39:59,240 INFO: blog startup [in /home/jessah/blog/app/__init__.py:41]
2021-01-24 14:40:00,540 ERROR: Exception on /user/CJ [GET] [in /home/jessah/blog/venv/lib/python3.8/site-packages/flask/app.py:1891]
Traceback (most recent call last):
  File "/home/jessah/blog/venv/lib/python3.8/site-packages/flask/app.py", line 2447, in wsgi_app
    response = self.full_dispatch_request()
  File "/home/jessah/blog/venv/lib/python3.8/site-packages/flask/app.py", line 1952, in full_dispatch_request
    rv = self.handle_user_exception(e)
  File "/home/jessah/blog/venv/lib/python3.8/site-packages/flask/app.py", line 1821, in handle_user_exception
    reraise(exc_type, exc_value, tb)
  File "/home/jessah/blog/venv/lib/python3.8/site-packages/flask/_compat.py", line 39, in reraise
    raise value
  File "/home/jessah/blog/venv/lib/python3.8/site-packages/flask/app.py", line 1950, in full_dispatch_request
    rv = self.dispatch_request()
  File "/home/jessah/blog/venv/lib/python3.8/site-packages/flask/app.py", line 1936, in dispatch_request
    return self.view_functions[rule.endpoint](**req.view_args)
  File "/home/jessah/blog/venv/lib/python3.8/site-packages/flask_login/utils.py", line 272, in decorated_view
    return func(*args, **kwargs)
  File "/home/jessah/blog/app/routes.py", line 71, in user
    posts = user.posts.order_by(Post.timestamp,desc()).paginate(
NameError: name 'desc' is not defined
2021-01-24 14:41:10,293 INFO: blog startup [in /home/jessah/blog/app/__init__.py:41]
2021-01-24 14:41:13,691 ERROR: Exception on /user/CJ [GET] [in /home/jessah/blog/venv/lib/python3.8/site-packages/flask/app.py:1891]
Traceback (most recent call last):
  File "/home/jessah/blog/venv/lib/python3.8/site-packages/flask/app.py", line 2447, in wsgi_app
    response = self.full_dispatch_request()
  File "/home/jessah/blog/venv/lib/python3.8/site-packages/flask/app.py", line 1952, in full_dispatch_request
    rv = self.handle_user_exception(e)
  File "/home/jessah/blog/venv/lib/python3.8/site-packages/flask/app.py", line 1821, in handle_user_exception
    reraise(exc_type, exc_value, tb)
  File "/home/jessah/blog/venv/lib/python3.8/site-packages/flask/_compat.py", line 39, in reraise
    raise value
  File "/home/jessah/blog/venv/lib/python3.8/site-packages/flask/app.py", line 1950, in full_dispatch_request
    rv = self.dispatch_request()
  File "/home/jessah/blog/venv/lib/python3.8/site-packages/flask/app.py", line 1936, in dispatch_request
    return self.view_functions[rule.endpoint](**req.view_args)
  File "/home/jessah/blog/venv/lib/python3.8/site-packages/flask_login/utils.py", line 272, in decorated_view
    return func(*args, **kwargs)
  File "/home/jessah/blog/app/routes.py", line 72, in user
    page, app.config['POSTS_PER_PAGE'], False)
NameError: name 'page' is not defined
2021-01-24 14:43:05,335 INFO: blog startup [in /home/jessah/blog/app/__init__.py:41]
